<?xml version="1.0" ?>
<!-- =================================================================================== -->
<!-- |    This document was autogenerated by xacro from atlas.urdf.xacro               | -->
<!-- |    EDITING THIS FILE BY HAND IS NOT RECOMMENDED                                 | -->
<!-- =================================================================================== -->
<robot name="atlas" xmlns:xacro="http://www.ros.org/wiki/xacro">

    <!--foot-->
    <link name="r_foot">
      <inertial>
        <mass value="1.634"/>
        <origin rpy="0 -0 0" xyz="0.027 0 -0.067"/>
        <inertia ixx="0.002" ixy="0" ixz="0" iyy="0.007" iyz="0" izz="0.008"/>
      </inertial>
      <visual>
        <origin rpy="0 -0 0" xyz="0 0 0"/>
        <geometry>
          <mesh filename="package://atlas_description/meshes/r_foot.dae" scale="1 1 1"/>
        </geometry>
      </visual>
      <!-- bottom -->
      <collision>
        <origin rpy="0 0 0" xyz="0.048 0 -0.056119"/>
        <geometry>
          <box size="0.26 0.124887 0.05"/>
        </geometry>
      </collision>
    </link>


  <link name="r_talus">
    <inertial>
      <mass value="0.1"/>
      <origin rpy="0 -0 0" xyz="0 0 0"/>
      <inertia ixx="1.01674e-05" ixy="0" ixz="0" iyy="8.42775e-06" iyz="0" izz="1.30101e-05"/>
    </inertial>
    <visual>
      <origin rpy="0 -0 0" xyz="0 0 0"/>
      <geometry>
        <mesh filename="package://atlas_description/meshes/r_talus.dae" scale="1 1 1"/>
      </geometry>
    </visual>
    <collision>
      <origin rpy="0 1.5707963267949 0" xyz="0 0 0"/>
      <geometry>
        <cylinder length="0.029542" radius="0.010181"/>
      </geometry>
    </collision>
    <collision>
      <origin rpy="1.5707963267949 0 0" xyz="0 0 0"/>
      <geometry>
        <cylinder length="0.010059" radius="0.010348"/>
      </geometry>
    </collision>
  </link>


  <link name="r_lleg">
    <inertial>
      <mass value="4.367"/>
      <origin rpy="0 -0 0" xyz="0.001 0 -0.187"/>
      <inertia ixx="0.077" ixy="-0" ixz="-0.003" iyy="0.076" iyz="-0" izz="0.01"/>
    </inertial>
    <visual>
      <origin rpy="0 -0 0" xyz="0 0 0"/>
      <geometry>
        <mesh filename="package://atlas_description/meshes/r_lleg.dae" scale="1.0 1.0 1.0"/>
      </geometry>
    </visual>
    <collision>
      <origin rpy="0 0.10 0" xyz="0.02 -0.00295 -0.18"/>
      <geometry>
        <cylinder length="0.40" radius="0.07"/>
      </geometry>
    </collision>
  </link>


  <link name="r_uleg">
    <inertial>
      <mass value="7.34"/>
      <origin rpy="0 -0 0" xyz="0 0 -0.21"/>
      <inertia ixx="0.09" ixy="0" ixz="0" iyy="0.09" iyz="0" izz="0.02"/>
    </inertial>
    <visual>
      <origin rpy="0 -0 0" xyz="0 0 0"/>
      <geometry>
        <mesh filename="package://atlas_description/meshes/r_uleg.dae" scale="1.0 1.0 1.0"/>
      </geometry>
    </visual>
    <collision>
      <origin rpy="0 0 0" xyz="-0.0179 -0.02085 -0.13"/>
      <geometry>
        <cylinder length="0.10" radius="0.1"/>
      </geometry>
    </collision>
    <collision>
      <origin rpy="0 -0.3 0" xyz="-0.03 -0.01 -0.23"/>
      <geometry>
        <cylinder length="0.15" radius="0.07"/>
      </geometry>
    </collision>
    <collision>
      <origin rpy="0 0.3 0" xyz="-0.005 -0.01 -0.23"/>
      <geometry>
        <cylinder length="0.15" radius="0.07"/>
      </geometry>
    </collision>
    <collision>
      <origin rpy="0.25 0 0" xyz="-0.02 -0.03 -0.23"/>
      <geometry>
        <cylinder length="0.15" radius="0.07"/>
      </geometry>
    </collision>
  </link>


  <link name="r_lglut">
    <inertial>
      <mass value="0.69"/>
      <origin rpy="0 -0 0" xyz="0.0133341 -0.0170484 -0.0312052"/>
      <inertia ixx="0.000691326" ixy="2.24344e-05" ixz="2.50508e-06" iyy="0.00126856" iyz="-0.000137862" izz="0.00106487"/>
    </inertial>
    <visual>
      <origin rpy="0 -0 0" xyz="0 0 0"/>
      <geometry>
        <mesh filename="package://atlas_description/meshes/r_lglut.dae" scale="1.0 1.0 1.0"/>
      </geometry>
    </visual>
    <collision>
      <origin rpy="1.5707963267949 0 0" xyz="0.049968 -0.022488 -0.0501165"/>
      <geometry>
        <cylinder length="0.060306" radius="0.02009687"/>
      </geometry>
    </collision>
    <collision>
      <origin rpy="0 1.5707963267949 0" xyz="0 0 0"/>
      <geometry>
        <cylinder length="0.12" radius="0.02"/>
      </geometry>
    </collision>
  </link>


  <link name="r_uglut">
    <inertial>
      <mass value="0.5166"/>
      <origin rpy="0 -0 0" xyz="0.00529262 0.00344732 0.00313046"/>
      <inertia ixx="0.00074276" ixy="3.79607e-08" ixz="-2.79549e-05" iyy="0.000688179" iyz="3.2735e-08" izz="0.00041242"/>
    </inertial>
    <visual>
      <origin rpy="0 -0 0" xyz="0 0 0"/>
      <geometry>
        <mesh filename="package://atlas_description/meshes/r_uglut.dae" scale="1.0 1.0 1.0"/>
      </geometry>
    </visual>
    <collision>
      <origin rpy="0 1.5707963267949 0" xyz="0 0 0"/>
      <geometry>
        <cylinder length="0.078396" radius="0.019096"/>
      </geometry>
    </collision>
    <collision>
      <origin rpy="0 0 0" xyz="0 0 0"/>
      <geometry>
        <cylinder length="0.080842" radius="0.019841"/>
      </geometry>
    </collision>
  </link>


  <link name="pelvis">
    <inertial>
      <mass value="14.2529"/>
      <origin rpy="0 -0 0" xyz="0.0111 0 0.0271"/>
      <inertia ixx="0.1244" ixy="0.0008" ixz="-0.0007" iyy="0.0958" iyz="-0.0005" izz="0.1167"/>
    </inertial>
    <visual>
      <origin rpy="0 -0 0" xyz="0 0 0"/>
      <geometry>
        <mesh filename="package://atlas_description/meshes/pelvis.dae" scale="1.0 1.0 1.0"/>
      </geometry>
    </visual>
    <collision>
      <origin rpy="1.5707963267949 0 0" xyz="0.046 0.0 -0.02"/>
      <geometry>
        <cylinder length="0.06" radius="0.11"/>
      </geometry>
    </collision>
    <collision>
      <origin rpy="1.5707963267949 0 0" xyz="-0.03 0.0 -0.02"/>
      <geometry>
        <cylinder length="0.06" radius="0.11"/>
      </geometry>
    </collision>
    <collision>
      <origin rpy="0 0 0" xyz="0.01 0.042 0.09"/>
      <geometry>
        <cylinder length="0.05" radius="0.16"/>
      </geometry>
    </collision>
    <collision>
      <origin rpy="0 0 0" xyz="0.01 -0.042 0.09"/>
      <geometry>
        <cylinder length="0.05" radius="0.16"/>
      </geometry>
    </collision>
    <collision>
      <origin rpy="0 0 0" xyz="-0.1 0 -0.05"/>
      <geometry>
        <box size="0.1 0.15 0.2"/>
      </geometry>
    </collision>
  </link>
<!---joint----->
<joint name="r_leg_lax" type="revolute">
  <origin rpy="0 -0 0" xyz="0 0 0"/>
  <axis xyz="1 0 0"/>
  <parent link="r_talus"/>
  <child link="r_foot"/>
  <dynamics damping="1.0" friction="0"/>
  <limit effort="90" lower="-0.436" upper="0.436" velocity="12"/>
  <safety_controller k_position="100" k_velocity="100" soft_lower_limit="-10.436" soft_upper_limit="10.436"/>
</joint>


  <joint name="r_leg_uay" type="revolute">
    <origin rpy="0 -0 0" xyz="0 0 -0.422"/>
    <axis xyz="0 1 0"/>
    <parent link="r_lleg"/>
    <child link="r_talus"/>
    <dynamics damping="1.0" friction="0"/>
    <limit effort="220" lower="-0.9" upper="0.698" velocity="12"/>
    <safety_controller k_position="100" k_velocity="100" soft_lower_limit="-10.698" soft_upper_limit="10.698"/>
  </joint>


  <joint name="r_leg_kny" type="revolute">
    <origin rpy="0 -0 0" xyz="-0.05 0 -0.374"/>
    <axis xyz="0 1 0"/>
    <parent link="r_uleg"/>
    <child link="r_lleg"/>
    <dynamics damping="1.0" friction="0"/>
    <limit effort="400" lower="0" upper="2.45" velocity="12"/>
    <safety_controller k_position="100" k_velocity="100" soft_lower_limit="-10" soft_upper_limit="12.45"/>
  </joint>


  <joint name="r_leg_lhy" type="revolute">
    <origin rpy="0 -0 0" xyz="0.05 0 -0.05"/>
    <axis xyz="0 1 0"/>
    <parent link="r_lglut"/>
    <child link="r_uleg"/>
    <dynamics damping="1.0" friction="0"/>
    <limit effort="260" lower="-1.745" upper="0.524" velocity="12"/>
    <safety_controller k_position="100" k_velocity="100" soft_lower_limit="-11.745" soft_upper_limit="10.524"/>
  </joint>

  <joint name="r_leg_mhx" type="revolute">
    <origin rpy="0 -0 0" xyz="0 0 0"/>
    <axis xyz="1 0 0"/>
    <parent link="r_uglut"/>
    <child link="r_lglut"/>
    <dynamics damping="1.0" friction="0"/>
    <limit effort="180" lower="-0.495" upper="0.47" velocity="12"/>
    <safety_controller k_position="100" k_velocity="100" soft_lower_limit="-10.495" soft_upper_limit="10.47"/>
  </joint>

  <joint name="r_leg_uhz" type="revolute">
    <origin rpy="0 -0 0" xyz="0 -0.089 0"/>
    <axis xyz="0 0 1"/>
    <parent link="pelvis"/>
    <child link="r_uglut"/>
    <dynamics damping="1.0" friction="0"/>
    <limit effort="110" lower="-1.14" upper="0.32" velocity="12"/>
    <safety_controller k_position="100" k_velocity="100" soft_lower_limit="-11.14" soft_upper_limit="10.32"/>
  </joint>
</robot>

